[INFO] [2025-06-04 15:50:01,028] - main: App Started
[INFO] [2025-06-04 15:50:01,374] - pages: 'Start' page was openned
[INFO] [2025-06-04 15:50:07,663] - pages: 'Main' page was openned
[INFO] [2025-06-04 15:52:56,848] - main: App Started
[INFO] [2025-06-04 15:52:57,102] - pages: 'Start' page was openned
[INFO] [2025-06-04 15:52:59,716] - pages: 'Main' page was openned
[INFO] [2025-06-04 15:53:25,503] - main: App Started
[INFO] [2025-06-04 15:53:25,756] - pages: 'Start' page was openned
[INFO] [2025-06-04 15:53:28,747] - pages: 'Main' page was openned
[INFO] [2025-06-04 15:53:39,601] - pages: 'Main' page was openned
[INFO] [2025-06-04 15:59:10,131] - main: App Started
[INFO] [2025-06-04 15:59:10,376] - pages: 'Start' page was openned
[INFO] [2025-06-04 15:59:16,694] - main: App Started
[INFO] [2025-06-04 15:59:16,925] - pages: 'Start' page was openned
[ERROR] [2025-06-04 15:59:20,310] - pages:  list assignment index out of range
Traceback (most recent call last):
  File "/Users/who/Coding/Python/UnimportantProject_HAMT/utilits/utilits_desktop.py", line 171, in pageClose
    lines[0]=f"Enter Today:{datetime.datetime.now().strftime('%D')}"
    ~~~~~^^^
IndexError: list assignment index out of range
[ERROR] [2025-06-04 15:59:20,313] - asyncio: Future exception was never retrieved
future: <Future finished exception=Exception(' list assignment index out of range')>
Traceback (most recent call last):
  File "/Users/who/Coding/Python/UnimportantProject_HAMT/utilits/utilits_desktop.py", line 171, in pageClose
    lines[0]=f"Enter Today:{datetime.datetime.now().strftime('%D')}"
    ~~~~~^^^
IndexError: list assignment index out of range

During handling of the above exception, another exception occurred:

Traceback (most recent call last):
  File "/Library/Frameworks/Python.framework/Versions/3.13/lib/python3.13/concurrent/futures/thread.py", line 59, in run
    result = self.fn(*self.args, **self.kwargs)
  File "/Library/Frameworks/Python.framework/Versions/3.13/lib/python3.13/site-packages/flet/core/page.py", line 903, in wrapper
    handler(*args)
    ~~~~~~~^^^^^^^
  File "/Users/who/Coding/Python/UnimportantProject_HAMT/utilits/utilits_desktop.py", line 177, in pageClose
    raise Exception(f" {ex}")
Exception:  list assignment index out of range
[ERROR] [2025-06-04 15:59:22,577] - pages:  list assignment index out of range
Traceback (most recent call last):
  File "/Users/who/Coding/Python/UnimportantProject_HAMT/utilits/utilits_desktop.py", line 171, in pageClose
    lines[0]=f"Enter Today:{datetime.datetime.now().strftime('%D')}"
    ~~~~~^^^
IndexError: list assignment index out of range
[ERROR] [2025-06-04 15:59:22,578] - asyncio: Future exception was never retrieved
future: <Future finished exception=Exception(' list assignment index out of range')>
Traceback (most recent call last):
  File "/Users/who/Coding/Python/UnimportantProject_HAMT/utilits/utilits_desktop.py", line 171, in pageClose
    lines[0]=f"Enter Today:{datetime.datetime.now().strftime('%D')}"
    ~~~~~^^^
IndexError: list assignment index out of range

During handling of the above exception, another exception occurred:

Traceback (most recent call last):
  File "/Library/Frameworks/Python.framework/Versions/3.13/lib/python3.13/concurrent/futures/thread.py", line 59, in run
    result = self.fn(*self.args, **self.kwargs)
  File "/Library/Frameworks/Python.framework/Versions/3.13/lib/python3.13/site-packages/flet/core/page.py", line 903, in wrapper
    handler(*args)
    ~~~~~~~^^^^^^^
  File "/Users/who/Coding/Python/UnimportantProject_HAMT/utilits/utilits_desktop.py", line 177, in pageClose
    raise Exception(f" {ex}")
Exception:  list assignment index out of range
[ERROR] [2025-06-04 15:59:23,159] - pages:  list assignment index out of range
Traceback (most recent call last):
  File "/Users/who/Coding/Python/UnimportantProject_HAMT/utilits/utilits_desktop.py", line 171, in pageClose
    lines[0]=f"Enter Today:{datetime.datetime.now().strftime('%D')}"
    ~~~~~^^^
IndexError: list assignment index out of range
[ERROR] [2025-06-04 15:59:23,160] - asyncio: Future exception was never retrieved
future: <Future finished exception=Exception(' list assignment index out of range')>
Traceback (most recent call last):
  File "/Users/who/Coding/Python/UnimportantProject_HAMT/utilits/utilits_desktop.py", line 171, in pageClose
    lines[0]=f"Enter Today:{datetime.datetime.now().strftime('%D')}"
    ~~~~~^^^
IndexError: list assignment index out of range

During handling of the above exception, another exception occurred:

Traceback (most recent call last):
  File "/Library/Frameworks/Python.framework/Versions/3.13/lib/python3.13/concurrent/futures/thread.py", line 59, in run
    result = self.fn(*self.args, **self.kwargs)
  File "/Library/Frameworks/Python.framework/Versions/3.13/lib/python3.13/site-packages/flet/core/page.py", line 903, in wrapper
    handler(*args)
    ~~~~~~~^^^^^^^
  File "/Users/who/Coding/Python/UnimportantProject_HAMT/utilits/utilits_desktop.py", line 177, in pageClose
    raise Exception(f" {ex}")
Exception:  list assignment index out of range
[ERROR] [2025-06-04 15:59:23,360] - pages:  list assignment index out of range
Traceback (most recent call last):
  File "/Users/who/Coding/Python/UnimportantProject_HAMT/utilits/utilits_desktop.py", line 171, in pageClose
    lines[0]=f"Enter Today:{datetime.datetime.now().strftime('%D')}"
    ~~~~~^^^
IndexError: list assignment index out of range
[ERROR] [2025-06-04 15:59:23,361] - asyncio: Future exception was never retrieved
future: <Future finished exception=Exception(' list assignment index out of range')>
Traceback (most recent call last):
  File "/Users/who/Coding/Python/UnimportantProject_HAMT/utilits/utilits_desktop.py", line 171, in pageClose
    lines[0]=f"Enter Today:{datetime.datetime.now().strftime('%D')}"
    ~~~~~^^^
IndexError: list assignment index out of range

During handling of the above exception, another exception occurred:

Traceback (most recent call last):
  File "/Library/Frameworks/Python.framework/Versions/3.13/lib/python3.13/concurrent/futures/thread.py", line 59, in run
    result = self.fn(*self.args, **self.kwargs)
  File "/Library/Frameworks/Python.framework/Versions/3.13/lib/python3.13/site-packages/flet/core/page.py", line 903, in wrapper
    handler(*args)
    ~~~~~~~^^^^^^^
  File "/Users/who/Coding/Python/UnimportantProject_HAMT/utilits/utilits_desktop.py", line 177, in pageClose
    raise Exception(f" {ex}")
Exception:  list assignment index out of range
[ERROR] [2025-06-04 15:59:23,526] - pages:  list assignment index out of range
Traceback (most recent call last):
  File "/Users/who/Coding/Python/UnimportantProject_HAMT/utilits/utilits_desktop.py", line 171, in pageClose
    lines[0]=f"Enter Today:{datetime.datetime.now().strftime('%D')}"
    ~~~~~^^^
IndexError: list assignment index out of range
[ERROR] [2025-06-04 15:59:23,527] - asyncio: Future exception was never retrieved
future: <Future finished exception=Exception(' list assignment index out of range')>
Traceback (most recent call last):
  File "/Users/who/Coding/Python/UnimportantProject_HAMT/utilits/utilits_desktop.py", line 171, in pageClose
    lines[0]=f"Enter Today:{datetime.datetime.now().strftime('%D')}"
    ~~~~~^^^
IndexError: list assignment index out of range

During handling of the above exception, another exception occurred:

Traceback (most recent call last):
  File "/Library/Frameworks/Python.framework/Versions/3.13/lib/python3.13/concurrent/futures/thread.py", line 59, in run
    result = self.fn(*self.args, **self.kwargs)
  File "/Library/Frameworks/Python.framework/Versions/3.13/lib/python3.13/site-packages/flet/core/page.py", line 903, in wrapper
    handler(*args)
    ~~~~~~~^^^^^^^
  File "/Users/who/Coding/Python/UnimportantProject_HAMT/utilits/utilits_desktop.py", line 177, in pageClose
    raise Exception(f" {ex}")
Exception:  list assignment index out of range
[INFO] [2025-06-04 16:00:41,076] - main: App Started
[INFO] [2025-06-04 16:00:41,312] - pages: 'Start' page was openned
[INFO] [2025-06-04 16:00:58,666] - main: App Started
[INFO] [2025-06-04 16:00:58,925] - pages: 'Start' page was openned
[INFO] [2025-06-04 16:01:10,004] - main: App Started
[INFO] [2025-06-04 16:01:10,260] - pages: 'Start' page was openned
[INFO] [2025-06-04 16:02:00,620] - main: App Started
[INFO] [2025-06-04 16:02:00,866] - pages: 'Start' page was openned
[INFO] [2025-06-04 16:02:03,525] - pages: 'Main' page was openned
[INFO] [2025-06-04 16:22:24,939] - main: App Started
[INFO] [2025-06-04 16:22:25,265] - pages: 'Start' page was openned
[INFO] [2025-06-04 16:23:12,163] - pages: 'Main' page was openned
[INFO] [2025-06-04 16:25:19,508] - main: App Started
[INFO] [2025-06-04 16:25:19,827] - pages: 'Start' page was openned
[INFO] [2025-06-04 16:25:24,536] - pages: 'Main' page was openned
[ERROR] [2025-06-04 16:29:48,740] - asyncio: Future exception was never retrieved
future: <Future finished exception=TypeError("checkEqAdd_OnIncosist() missing 1 required positional argument: 'table_obj'")>
Traceback (most recent call last):
  File "/Library/Frameworks/Python.framework/Versions/3.13/lib/python3.13/concurrent/futures/thread.py", line 59, in run
    result = self.fn(*self.args, **self.kwargs)
  File "/Library/Frameworks/Python.framework/Versions/3.13/lib/python3.13/site-packages/flet/core/page.py", line 903, in wrapper
    handler(*args)
    ~~~~~~~^^^^^^^
  File "/Users/who/Coding/Python/UnimportantProject_HAMT/Desktop/pages.py", line 27, in addData
    if(deskU.checkEqAdd_OnIncosist(self.page.controls)):
       ~~~~~~~~~~~~~~~~~~~~~~~~~~~^^^^^^^^^^^^^^^^^^^^
TypeError: checkEqAdd_OnIncosist() missing 1 required positional argument: 'table_obj'
[INFO] [2025-06-04 16:36:26,313] - main: App Started
[INFO] [2025-06-04 16:36:26,633] - pages: 'Start' page was openned
[INFO] [2025-06-04 16:36:41,256] - pages: 'Main' page was openned
[INFO] [2025-06-04 16:39:41,548] - main: App Started
[INFO] [2025-06-04 16:39:41,850] - pages: 'Start' page was openned
[INFO] [2025-06-04 16:39:45,316] - pages: 'Main' page was openned
[INFO] [2025-06-04 16:42:07,459] - main: App Started
[INFO] [2025-06-04 16:42:07,721] - pages: 'Start' page was openned
[INFO] [2025-06-04 16:42:16,471] - pages: 'Main' page was openned
[ERROR] [2025-06-04 16:43:45,115] - asyncio: Future exception was never retrieved
future: <Future finished exception=Exception("object of type 'bool' has no len()")>
Traceback (most recent call last):
  File "/Users/who/Coding/Python/UnimportantProject_HAMT/utilits/utilits_desktop.py", line 111, in checkEqAdd_OnIncosist
    if (control.label=='IP-адрес' and len(control.value.split('.')!=4)):
                                      ~~~^^^^^^^^^^^^^^^^^^^^^^^^^^^^^
TypeError: object of type 'bool' has no len()

During handling of the above exception, another exception occurred:

Traceback (most recent call last):
  File "/Library/Frameworks/Python.framework/Versions/3.13/lib/python3.13/concurrent/futures/thread.py", line 59, in run
    result = self.fn(*self.args, **self.kwargs)
  File "/Library/Frameworks/Python.framework/Versions/3.13/lib/python3.13/site-packages/flet/core/page.py", line 903, in wrapper
    handler(*args)
    ~~~~~~~^^^^^^^
  File "/Users/who/Coding/Python/UnimportantProject_HAMT/Desktop/pages.py", line 27, in addData
    if(deskU.checkEqAdd_OnIncosist(self_main.page.controls[1].controls)):
       ~~~~~~~~~~~~~~~~~~~~~~~~~~~^^^^^^^^^^^^^^^^^^^^^^^^^^^^^^^^^^^^^
  File "/Users/who/Coding/Python/UnimportantProject_HAMT/utilits/utilits_desktop.py", line 124, in checkEqAdd_OnIncosist
    raise Exception(f'{ex}')
Exception: object of type 'bool' has no len()
[INFO] [2025-06-04 16:44:36,031] - main: App Started
[INFO] [2025-06-04 16:44:36,373] - pages: 'Start' page was openned
[INFO] [2025-06-04 16:44:43,849] - pages: 'Main' page was openned
[INFO] [2025-06-04 16:46:16,886] - main: App Started
[INFO] [2025-06-04 16:46:17,136] - pages: 'Start' page was openned
[INFO] [2025-06-04 16:46:21,609] - pages: 'Main' page was openned
[INFO] [2025-06-04 16:48:51,289] - main: App Started
[INFO] [2025-06-04 16:48:51,554] - pages: 'Start' page was openned
[INFO] [2025-06-04 16:51:32,177] - pages: 'Main' page was openned
[INFO] [2025-06-04 16:52:58,702] - main: App Started
[INFO] [2025-06-04 16:52:58,933] - pages: 'Start' page was openned
[INFO] [2025-06-04 16:53:01,674] - pages: 'Main' page was openned
