[INFO] [2025-04-05 13:48:02,544] - main: App Started
[INFO] [2025-04-05 13:48:02,714] - database: Connected to database was successfull
[INFO] [2025-04-05 13:48:04,786] - pages: 'Start' page was openned
[INFO] [2025-04-05 13:51:14,687] - main: App Started
[INFO] [2025-04-05 13:51:14,769] - database: Connected to database was successfull
[INFO] [2025-04-05 13:51:15,158] - pages: 'Start' page was openned
[INFO] [2025-04-06 21:23:54,771] - main: App Started
[INFO] [2025-04-06 21:23:54,952] - database: Connected to database was successfull
[INFO] [2025-04-06 21:23:56,605] - pages: 'Start' page was openned
[INFO] [2025-04-15 11:36:34,131] - main: App Started
[INFO] [2025-04-15 11:36:34,203] - database: Connected to database was successfull
[INFO] [2025-04-15 11:36:35,454] - pages: 'StartAdmin' page was openned
[INFO] [2025-04-15 11:47:53,908] - main: App Started
[INFO] [2025-04-15 11:47:54,097] - database: Connected to database was successfull
[INFO] [2025-04-15 11:47:54,564] - pages: 'StartAdmin' page was openned
[INFO] [2025-04-15 11:48:35,353] - main: App Started
[INFO] [2025-04-15 11:48:35,429] - database: Connected to database was successfull
[INFO] [2025-04-15 11:48:35,812] - pages: 'StartAdmin' page was openned
[INFO] [2025-04-15 11:48:55,597] - main: App Started
[INFO] [2025-04-15 11:48:55,649] - database: Connected to database was successfull
[INFO] [2025-04-15 11:48:56,081] - pages: 'StartAdmin' page was openned
[INFO] [2025-04-15 11:49:29,783] - main: App Started
[INFO] [2025-04-15 11:49:30,010] - database: Connected to database was successfull
[INFO] [2025-04-15 11:49:30,477] - pages: 'StartAdmin' page was openned
[INFO] [2025-04-15 11:49:49,796] - main: App Started
[INFO] [2025-04-15 11:49:49,885] - database: Connected to database was successfull
[INFO] [2025-04-15 11:49:50,297] - pages: 'StartAdmin' page was openned
[INFO] [2025-04-15 11:50:16,186] - main: App Started
[INFO] [2025-04-15 11:50:16,260] - database: Connected to database was successfull
[INFO] [2025-04-15 11:50:16,664] - pages: 'StartAdmin' page was openned
[INFO] [2025-04-15 11:50:31,775] - main: App Started
[INFO] [2025-04-15 11:50:31,849] - database: Connected to database was successfull
[INFO] [2025-04-15 11:50:32,391] - pages: 'StartAdmin' page was openned
[INFO] [2025-04-15 11:51:03,845] - main: App Started
[INFO] [2025-04-15 11:51:03,942] - database: Connected to database was successfull
[INFO] [2025-04-15 11:51:04,480] - pages: 'StartAdmin' page was openned
[INFO] [2025-04-15 11:52:05,705] - main: App Started
[INFO] [2025-04-15 11:52:05,839] - database: Connected to database was successfull
[INFO] [2025-04-15 11:52:06,289] - pages: 'StartAdmin' page was openned
[INFO] [2025-04-15 11:53:07,339] - main: App Started
[INFO] [2025-04-15 11:53:07,535] - database: Connected to database was successfull
[INFO] [2025-04-15 11:53:07,959] - pages: 'StartAdmin' page was openned
[INFO] [2025-04-15 11:53:37,190] - main: App Started
[INFO] [2025-04-15 11:53:37,266] - database: Connected to database was successfull
[INFO] [2025-04-15 11:53:37,689] - pages: 'StartAdmin' page was openned
[INFO] [2025-04-15 11:53:52,543] - main: App Started
[INFO] [2025-04-15 11:53:52,618] - database: Connected to database was successfull
[INFO] [2025-04-15 11:53:53,014] - pages: 'StartAdmin' page was openned
[INFO] [2025-04-15 11:54:40,493] - main: App Started
[INFO] [2025-04-15 11:54:40,711] - database: Connected to database was successfull
[INFO] [2025-04-15 11:54:41,137] - pages: 'StartAdmin' page was openned
[INFO] [2025-04-15 12:04:58,179] - main: App Started
[INFO] [2025-04-15 12:04:58,399] - database: Connected to database was successfull
[INFO] [2025-04-15 12:04:58,845] - pages: 'StartAdmin' page was openned
[INFO] [2025-04-15 12:06:04,334] - main: App Started
[INFO] [2025-04-15 12:06:04,534] - database: Connected to database was successfull
[INFO] [2025-04-15 12:06:04,922] - pages: 'StartAdmin' page was openned
[INFO] [2025-04-15 12:06:41,546] - main: App Started
[INFO] [2025-04-15 12:06:41,626] - database: Connected to database was successfull
[INFO] [2025-04-15 12:06:42,026] - pages: 'StartAdmin' page was openned
[INFO] [2025-04-15 12:09:21,583] - main: App Started
[INFO] [2025-04-15 12:09:21,657] - database: Connected to database was successfull
[INFO] [2025-04-15 12:09:22,050] - pages: 'StartAdmin' page was openned
[INFO] [2025-04-15 12:09:49,965] - main: App Started
[INFO] [2025-04-15 12:09:50,185] - database: Connected to database was successfull
[INFO] [2025-04-15 12:09:50,602] - pages: 'StartAdmin' page was openned
[INFO] [2025-04-15 12:10:46,623] - main: App Started
[INFO] [2025-04-15 12:10:46,851] - database: Connected to database was successfull
[INFO] [2025-04-15 12:10:47,279] - pages: 'StartAdmin' page was openned
[INFO] [2025-04-15 12:12:01,302] - main: App Started
[INFO] [2025-04-15 12:12:01,378] - database: Connected to database was successfull
[INFO] [2025-04-15 12:12:01,795] - pages: 'StartAdmin' page was openned
[INFO] [2025-04-15 12:12:22,691] - pages: 'Start' page was openned
[INFO] [2025-04-15 12:52:22,192] - main: App Started
[INFO] [2025-04-15 12:52:22,346] - database: Connected to database was successfull
[INFO] [2025-04-15 12:52:22,987] - pages: 'StartAdmin' page was openned
[ERROR] [2025-04-15 12:52:41,545] - asyncio: Future exception was never retrieved
future: <Future finished exception=FileNotFoundError(2, 'No such file or directory')>
Traceback (most recent call last):
  File "c:\Users\user\AppData\Local\Programs\Python\Python311\Lib\concurrent\futures\thread.py", line 58, in run
    result = self.fn(*self.args, **self.kwargs)
             ^^^^^^^^^^^^^^^^^^^^^^^^^^^^^^^^^^
  File "c:\Users\user\AppData\Local\Programs\Python\Python311\Lib\site-packages\flet\core\page.py", line 903, in wrapper
    handler(*args)
  File "E:\PROJECT\Python\NAMT_BOT\Git\UnimportantProject_HAMT\Desktop\pages.py", line 491, in backPage
    start_page(self.page,True)
  File "E:\PROJECT\Python\NAMT_BOT\Git\UnimportantProject_HAMT\Desktop\pages.py", line 441, in start_page
    with open("Admin Configure", 'r') as File:
         ^^^^^^^^^^^^^^^^^^^^^^^^^^^^
FileNotFoundError: [Errno 2] No such file or directory: 'Admin Configure'
[INFO] [2025-04-15 13:26:03,325] - main: App Started
[INFO] [2025-04-15 13:26:03,465] - database: Connected to database was successfull
[INFO] [2025-04-15 13:26:04,029] - pages: 'StartAdmin' page was openned
[INFO] [2025-04-15 13:28:11,494] - main: App Started
[INFO] [2025-04-15 13:28:11,546] - database: Connected to database was successfull
[INFO] [2025-04-15 13:28:12,024] - pages: 'StartAdmin' page was openned
[INFO] [2025-04-15 13:30:59,907] - main: App Started
[INFO] [2025-04-15 13:30:59,960] - database: Connected to database was successfull
[INFO] [2025-04-15 13:31:00,458] - pages: 'StartAdmin' page was openned
[ERROR] [2025-04-15 13:31:44,391] - database: Request execute was failed. Reason: ОШИБКА:  повторяющееся значение ключа нарушает ограничение уникальности "administators_pkey"
DETAIL:  Ключ "(login)=(who)" уже существует.

[ERROR] [2025-04-15 13:31:44,968] - asyncio: Future exception was never retrieved
future: <Future finished exception=Exception('Request execute was failed')>
Traceback (most recent call last):
  File "E:\PROJECT\Python\NAMT_BOT\Git\UnimportantProject_HAMT\utilits\bd.py", line 31, in reqExecute
    cursor.execute(request)
psycopg2.errors.UniqueViolation: ОШИБКА:  повторяющееся значение ключа нарушает ограничение уникальности "administators_pkey"
DETAIL:  Ключ "(login)=(who)" уже существует.


During handling of the above exception, another exception occurred:

Traceback (most recent call last):
  File "c:\Users\user\AppData\Local\Programs\Python\Python311\Lib\concurrent\futures\thread.py", line 58, in run
    result = self.fn(*self.args, **self.kwargs)
             ^^^^^^^^^^^^^^^^^^^^^^^^^^^^^^^^^^
  File "c:\Users\user\AppData\Local\Programs\Python\Python311\Lib\site-packages\flet\core\page.py", line 903, in wrapper
    handler(*args)
  File "E:\PROJECT\Python\NAMT_BOT\Git\UnimportantProject_HAMT\Desktop\pages.py", line 500, in adminRegInBD
    bd.reqExecute(f"Insert into Administators(FSL,Login, Password, TG_Username) values ('{fslField.value}', '{loginField.value}', '{passwordField.value}', '{usernameField.value}')")
  File "E:\PROJECT\Python\NAMT_BOT\Git\UnimportantProject_HAMT\utilits\bd.py", line 44, in reqExecute
    raise Exception("Request execute was failed")
Exception: Request execute was failed
[INFO] [2025-04-15 13:33:44,949] - main: App Started
[INFO] [2025-04-15 13:33:45,110] - database: Connected to database was successfull
[INFO] [2025-04-15 13:33:45,603] - pages: 'StartAdmin' page was openned
[INFO] [2025-04-15 13:35:57,849] - main: App Started
[INFO] [2025-04-15 13:35:57,910] - database: Connected to database was successfull
[INFO] [2025-04-15 13:36:06,067] - pages: 'Start' page was openned
[INFO] [2025-04-15 13:36:55,304] - main: App Started
[INFO] [2025-04-15 13:36:55,355] - database: Connected to database was successfull
[INFO] [2025-04-15 13:37:29,464] - main: App Started
[INFO] [2025-04-15 13:37:29,517] - database: Connected to database was successfull
[INFO] [2025-04-15 13:37:54,780] - main: App Started
[INFO] [2025-04-15 13:37:54,971] - database: Connected to database was successfull
[INFO] [2025-04-15 13:39:00,271] - main: App Started
[INFO] [2025-04-15 13:39:00,323] - database: Connected to database was successfull
[INFO] [2025-04-15 13:39:04,559] - pages: 'Start' page was openned
[INFO] [2025-04-15 13:39:11,238] - main: App Started
[INFO] [2025-04-15 13:39:11,463] - database: Connected to database was successfull
[INFO] [2025-04-15 13:39:34,903] - main: App Started
[INFO] [2025-04-15 13:39:35,074] - database: Connected to database was successfull
[INFO] [2025-04-15 13:39:52,012] - main: App Started
[INFO] [2025-04-15 13:39:52,065] - database: Connected to database was successfull
[INFO] [2025-04-15 13:39:58,755] - pages: 'Start' page was openned
[INFO] [2025-04-15 13:40:17,661] - main: App Started
[INFO] [2025-04-15 13:40:17,827] - database: Connected to database was successfull
[INFO] [2025-04-15 13:40:18,371] - pages: 'Start' page was openned
[INFO] [2025-04-15 13:40:37,455] - main: App Started
[INFO] [2025-04-15 13:40:37,510] - database: Connected to database was successfull
[INFO] [2025-04-15 13:40:37,927] - pages: 'Start' page was openned
[INFO] [2025-04-15 13:41:23,400] - main: App Started
[INFO] [2025-04-15 13:41:23,452] - database: Connected to database was successfull
[INFO] [2025-04-15 13:41:23,927] - pages: 'Start' page was openned
[INFO] [2025-04-15 13:41:56,260] - main: App Started
[INFO] [2025-04-15 13:41:56,311] - database: Connected to database was successfull
[INFO] [2025-04-15 13:41:56,743] - pages: 'Start' page was openned
[INFO] [2025-04-15 13:42:57,270] - main: App Started
[INFO] [2025-04-15 13:42:57,340] - database: Connected to database was successfull
[INFO] [2025-04-15 13:42:57,770] - pages: 'Start' page was openned
[INFO] [2025-04-15 13:45:53,922] - main: App Started
[INFO] [2025-04-15 13:45:53,974] - database: Connected to database was successfull
[INFO] [2025-04-15 13:45:54,418] - pages: 'Start' page was openned
[INFO] [2025-04-15 13:46:16,431] - main: App Started
[INFO] [2025-04-15 13:46:16,483] - database: Connected to database was successfull
[INFO] [2025-04-15 13:46:16,938] - pages: 'Start' page was openned
[INFO] [2025-04-15 13:47:18,026] - main: App Started
[INFO] [2025-04-15 13:47:18,091] - database: Connected to database was successfull
[INFO] [2025-04-15 13:47:18,591] - pages: 'Start' page was openned
[INFO] [2025-04-15 15:02:20,221] - main: App Started
[INFO] [2025-04-15 15:02:20,272] - database: Connected to database was successfull
[INFO] [2025-04-15 15:02:20,786] - pages: 'Start' page was openned
[INFO] [2025-04-15 16:39:50,379] - main: App Started
[INFO] [2025-04-15 16:39:50,532] - database: Connected to database was successfull
[INFO] [2025-04-15 16:41:04,884] - main: App Started
[INFO] [2025-04-15 16:41:05,103] - database: Connected to database was successfull
[INFO] [2025-04-15 16:41:05,820] - pages: 'Start' page was openned
[ERROR] [2025-04-15 16:41:18,978] - asyncio: Future exception was never retrieved
future: <Future finished exception=UnsupportedOperation('not readable')>
Traceback (most recent call last):
  File "c:\Users\user\AppData\Local\Programs\Python\Python311\Lib\concurrent\futures\thread.py", line 58, in run
    result = self.fn(*self.args, **self.kwargs)
             ^^^^^^^^^^^^^^^^^^^^^^^^^^^^^^^^^^
  File "c:\Users\user\AppData\Local\Programs\Python\Python311\Lib\site-packages\flet\core\page.py", line 903, in wrapper
    handler(*args)
  File "E:\PROJECT\Python\NAMT_BOT\Git\UnimportantProject_HAMT\utilits\utilits_desktop.py", line 184, in pageClose
    for line in file:
io.UnsupportedOperation: not readable
[INFO] [2025-04-15 16:42:08,172] - main: App Started
[INFO] [2025-04-15 16:42:08,232] - database: Connected to database was successfull
[INFO] [2025-04-15 16:42:08,702] - pages: 'Start' page was openned
[ERROR] [2025-04-15 16:42:37,323] - asyncio: Future exception was never retrieved
future: <Future finished exception=ValueError('I/O operation on closed file.')>
Traceback (most recent call last):
  File "c:\Users\user\AppData\Local\Programs\Python\Python311\Lib\concurrent\futures\thread.py", line 58, in run
    result = self.fn(*self.args, **self.kwargs)
             ^^^^^^^^^^^^^^^^^^^^^^^^^^^^^^^^^^
  File "c:\Users\user\AppData\Local\Programs\Python\Python311\Lib\site-packages\flet\core\page.py", line 903, in wrapper
    handler(*args)
  File "E:\PROJECT\Python\NAMT_BOT\Git\UnimportantProject_HAMT\utilits\utilits_desktop.py", line 184, in pageClose
    for line in file:
ValueError: I/O operation on closed file.
[INFO] [2025-04-15 16:44:18,212] - main: App Started
[INFO] [2025-04-15 16:44:18,262] - database: Connected to database was successfull
[INFO] [2025-04-15 16:44:18,717] - pages: 'Start' page was openned
[INFO] [2025-04-15 16:44:32,001] - main: App Started
[INFO] [2025-04-15 16:44:32,187] - database: Connected to database was successfull
[INFO] [2025-04-15 16:44:48,190] - main: App Started
[INFO] [2025-04-15 16:44:48,241] - database: Connected to database was successfull
[INFO] [2025-04-15 16:44:48,770] - pages: 'Start' page was openned
[INFO] [2025-04-15 16:46:18,431] - main: App Started
[INFO] [2025-04-15 16:46:18,490] - database: Connected to database was successfull
[INFO] [2025-04-15 16:46:18,957] - pages: 'Start' page was openned
[ERROR] [2025-04-15 16:46:21,367] - asyncio: Future exception was never retrieved
future: <Future finished exception=ValueError('Must have exactly one of create/read/write/append mode and at most one plus')>
Traceback (most recent call last):
  File "c:\Users\user\AppData\Local\Programs\Python\Python311\Lib\concurrent\futures\thread.py", line 58, in run
    result = self.fn(*self.args, **self.kwargs)
             ^^^^^^^^^^^^^^^^^^^^^^^^^^^^^^^^^^
  File "c:\Users\user\AppData\Local\Programs\Python\Python311\Lib\site-packages\flet\core\page.py", line 903, in wrapper
    handler(*args)
  File "E:\PROJECT\Python\NAMT_BOT\Git\UnimportantProject_HAMT\utilits\utilits_desktop.py", line 183, in pageClose
    with open("Admin Configure", '+') as file:
         ^^^^^^^^^^^^^^^^^^^^^^^^^^^^
ValueError: Must have exactly one of create/read/write/append mode and at most one plus
[INFO] [2025-04-15 16:46:56,819] - main: App Started
[INFO] [2025-04-15 16:46:56,877] - database: Connected to database was successfull
[INFO] [2025-04-15 16:46:57,412] - pages: 'Start' page was openned
[INFO] [2025-04-15 16:47:24,080] - main: App Started
[INFO] [2025-04-15 16:47:24,132] - database: Connected to database was successfull
[INFO] [2025-04-15 16:47:24,662] - pages: 'Start' page was openned
[ERROR] [2025-04-15 16:47:42,537] - asyncio: Future exception was never retrieved
future: <Future finished exception=ValueError('I/O operation on closed file.')>
Traceback (most recent call last):
  File "c:\Users\user\AppData\Local\Programs\Python\Python311\Lib\concurrent\futures\thread.py", line 58, in run
    result = self.fn(*self.args, **self.kwargs)
             ^^^^^^^^^^^^^^^^^^^^^^^^^^^^^^^^^^
  File "c:\Users\user\AppData\Local\Programs\Python\Python311\Lib\site-packages\flet\core\page.py", line 903, in wrapper
    handler(*args)
  File "E:\PROJECT\Python\NAMT_BOT\Git\UnimportantProject_HAMT\utilits\utilits_desktop.py", line 184, in pageClose
    for line in file:
ValueError: I/O operation on closed file.
[INFO] [2025-04-15 17:06:14,672] - main: App Started
[INFO] [2025-04-15 17:06:14,725] - database: Connected to database was successfull
[INFO] [2025-04-15 17:06:31,372] - main: App Started
[INFO] [2025-04-15 17:06:31,424] - database: Connected to database was successfull
[INFO] [2025-04-15 17:07:31,117] - main: App Started
[INFO] [2025-04-15 17:07:31,256] - database: Connected to database was successfull
[INFO] [2025-04-15 17:07:43,925] - pages: 'Start' page was openned
[INFO] [2025-04-15 17:08:04,183] - main: App Started
[INFO] [2025-04-15 17:08:04,239] - database: Connected to database was successfull
[INFO] [2025-04-15 17:08:07,181] - pages: 'Start' page was openned
[INFO] [2025-04-15 17:08:51,448] - main: App Started
[INFO] [2025-04-15 17:08:51,501] - database: Connected to database was successfull
[INFO] [2025-04-15 17:08:51,966] - pages: 'Start' page was openned
[INFO] [2025-04-15 17:09:08,155] - main: App Started
[INFO] [2025-04-15 17:09:08,208] - database: Connected to database was successfull
[INFO] [2025-04-15 17:09:08,657] - pages: 'Start' page was openned
[INFO] [2025-04-17 13:47:06,675] - main: App Started
[INFO] [2025-04-17 13:47:06,756] - database: Connected to database was successfull
[INFO] [2025-04-17 13:47:08,179] - pages: 'StartAdmin' page was openned
[ERROR] [2025-04-17 13:47:26,139] - asyncio: Future exception was never retrieved
future: <Future finished exception=FileNotFoundError(2, 'No such file or directory')>
Traceback (most recent call last):
  File "c:\Users\user\AppData\Local\Programs\Python\Python311\Lib\concurrent\futures\thread.py", line 58, in run
    result = self.fn(*self.args, **self.kwargs)
             ^^^^^^^^^^^^^^^^^^^^^^^^^^^^^^^^^^
  File "c:\Users\user\AppData\Local\Programs\Python\Python311\Lib\site-packages\flet\core\page.py", line 903, in wrapper
    handler(*args)
  File "E:\PROJECT\Python\NAMT_BOT\Git\UnimportantProject_HAMT\Desktop\pages.py", line 496, in backPage
    start_page(self.page,True)
  File "E:\PROJECT\Python\NAMT_BOT\Git\UnimportantProject_HAMT\Desktop\pages.py", line 448, in start_page
    with open("Admin Configure", 'r') as File:
         ^^^^^^^^^^^^^^^^^^^^^^^^^^^^
FileNotFoundError: [Errno 2] No such file or directory: 'Admin Configure'
[INFO] [2025-04-17 13:54:02,404] - main: App Started
[INFO] [2025-04-17 13:54:02,455] - database: Connected to database was successfull
[INFO] [2025-04-17 13:54:02,891] - pages: 'StartAdmin' page was openned
[INFO] [2025-04-17 13:55:20,898] - main: App Started
[INFO] [2025-04-17 13:55:21,052] - database: Connected to database was successfull
[INFO] [2025-04-17 13:55:21,579] - pages: 'StartAdmin' page was openned
[INFO] [2025-04-17 13:56:05,047] - main: App Started
[INFO] [2025-04-17 13:56:05,203] - database: Connected to database was successfull
[INFO] [2025-04-17 13:56:05,639] - pages: 'StartAdmin' page was openned
[INFO] [2025-04-17 13:57:57,456] - main: App Started
[INFO] [2025-04-17 13:57:57,596] - database: Connected to database was successfull
[INFO] [2025-04-17 13:57:58,316] - pages: 'StartAdmin' page was openned
[INFO] [2025-04-17 13:58:53,118] - main: App Started
[INFO] [2025-04-17 13:58:53,170] - database: Connected to database was successfull
[INFO] [2025-04-17 13:58:53,657] - pages: 'StartAdmin' page was openned
[INFO] [2025-04-17 14:06:28,310] - pages: 'Start' page was openned
[INFO] [2025-04-17 14:07:09,626] - main: App Started
[INFO] [2025-04-17 14:07:09,679] - database: Connected to database was successfull
[INFO] [2025-04-17 14:07:10,144] - pages: 'Start' page was openned
[INFO] [2025-04-17 14:07:44,295] - main: App Started
[INFO] [2025-04-17 14:07:44,348] - database: Connected to database was successfull
[INFO] [2025-04-17 14:07:44,787] - pages: 'Start' page was openned
[INFO] [2025-04-17 15:39:48,923] - main: App Started
[INFO] [2025-04-17 15:39:49,106] - database: Connected to database was successfull
[INFO] [2025-04-17 15:39:49,847] - pages: 'Start' page was openned
[INFO] [2025-04-17 15:40:12,922] - pages: 'Main' page was openned
[INFO] [2025-04-17 16:03:12,430] - main: App Started
[INFO] [2025-04-17 16:03:12,605] - database: Connected to database was successfull
[INFO] [2025-04-17 16:03:13,450] - pages: 'Start' page was openned
[INFO] [2025-04-17 16:07:45,069] - pages: 'Main' page was openned
[ERROR] [2025-04-17 16:09:57,788] - database: Request execute was failed. Reason: ОШИБКА:  текущая транзакция прервана, команды до конца блока транзакции игнорируются

[ERROR] [2025-04-17 16:09:58,405] - asyncio: Future exception was never retrieved
future: <Future finished exception=TypeError("object of type 'bool' has no len()")>
Traceback (most recent call last):
  File "c:\Users\user\AppData\Local\Programs\Python\Python311\Lib\concurrent\futures\thread.py", line 58, in run
    result = self.fn(*self.args, **self.kwargs)
             ^^^^^^^^^^^^^^^^^^^^^^^^^^^^^^^^^^
  File "c:\Users\user\AppData\Local\Programs\Python\Python311\Lib\site-packages\flet\core\page.py", line 903, in wrapper
    handler(*args)
  File "E:\PROJECT\Python\NAMT_BOT\Git\UnimportantProject_HAMT\Desktop\pages.py", line 27, in addData
    if (deskU.checkFieldOnIncosist(self,1)==True and len(bd.reqExecute(f"Select * from Equipment where Serial_Number='{serialNumber_field.value}'"))==0):
                                                     ^^^^^^^^^^^^^^^^^^^^^^^^^^^^^^^^^^^^^^^^^^^^^^^^^^^^^^^^^^^^^^^^^^^^^^^^^^^^^^^^^^^^^^^^^^^^^^^
TypeError: object of type 'bool' has no len()
[ERROR] [2025-04-17 16:09:58,483] - database: Request execute was failed. Reason: ОШИБКА:  неверный синтаксис для типа integer: ""
LINE 1: Select * from Equipment where Serial_Number=''
                                                    ^

[ERROR] [2025-04-17 16:09:59,345] - asyncio: Future exception was never retrieved
future: <Future finished exception=TypeError("object of type 'bool' has no len()")>
Traceback (most recent call last):
  File "c:\Users\user\AppData\Local\Programs\Python\Python311\Lib\concurrent\futures\thread.py", line 58, in run
    result = self.fn(*self.args, **self.kwargs)
             ^^^^^^^^^^^^^^^^^^^^^^^^^^^^^^^^^^
  File "c:\Users\user\AppData\Local\Programs\Python\Python311\Lib\site-packages\flet\core\page.py", line 903, in wrapper
    handler(*args)
  File "E:\PROJECT\Python\NAMT_BOT\Git\UnimportantProject_HAMT\Desktop\pages.py", line 27, in addData
    if (deskU.checkFieldOnIncosist(self,1)==True and len(bd.reqExecute(f"Select * from Equipment where Serial_Number='{serialNumber_field.value}'"))==0):
                                                     ^^^^^^^^^^^^^^^^^^^^^^^^^^^^^^^^^^^^^^^^^^^^^^^^^^^^^^^^^^^^^^^^^^^^^^^^^^^^^^^^^^^^^^^^^^^^^^^
TypeError: object of type 'bool' has no len()
[INFO] [2025-04-17 16:10:51,503] - main: App Started
[INFO] [2025-04-17 16:10:51,608] - database: Connected to database was successfull
[INFO] [2025-04-17 16:10:52,276] - pages: 'Start' page was openned
[INFO] [2025-04-17 16:10:57,929] - pages: 'Main' page was openned
[ERROR] [2025-04-17 16:11:01,051] - asyncio: Future exception was never retrieved
future: <Future finished exception=AttributeError("'Row' object has no attribute 'value'")>
Traceback (most recent call last):
  File "c:\Users\user\AppData\Local\Programs\Python\Python311\Lib\concurrent\futures\thread.py", line 58, in run
    result = self.fn(*self.args, **self.kwargs)
             ^^^^^^^^^^^^^^^^^^^^^^^^^^^^^^^^^^
  File "c:\Users\user\AppData\Local\Programs\Python\Python311\Lib\site-packages\flet\core\page.py", line 903, in wrapper
    handler(*args)
  File "E:\PROJECT\Python\NAMT_BOT\Git\UnimportantProject_HAMT\Desktop\pages.py", line 27, in addData
    if (deskU.checkFieldOnIncosist(self,1)==True and len(bd.reqExecute(f"Select * from Equipment where Serial_Number='{serialNumber_field.value}'"))==0):
        ^^^^^^^^^^^^^^^^^^^^^^^^^^^^^^^^^^
  File "E:\PROJECT\Python\NAMT_BOT\Git\UnimportantProject_HAMT\utilits\utilits_desktop.py", line 131, in checkFieldOnIncosist
    if (self.page.controls[i].value=="" or self.page.controls[i].value==None):
        ^^^^^^^^^^^^^^^^^^^^^^^^^^^
AttributeError: 'Row' object has no attribute 'value'
[ERROR] [2025-04-17 16:11:12,518] - asyncio: Future exception was never retrieved
future: <Future finished exception=AttributeError("'Row' object has no attribute 'value'")>
Traceback (most recent call last):
  File "c:\Users\user\AppData\Local\Programs\Python\Python311\Lib\concurrent\futures\thread.py", line 58, in run
    result = self.fn(*self.args, **self.kwargs)
             ^^^^^^^^^^^^^^^^^^^^^^^^^^^^^^^^^^
  File "c:\Users\user\AppData\Local\Programs\Python\Python311\Lib\site-packages\flet\core\page.py", line 903, in wrapper
    handler(*args)
  File "E:\PROJECT\Python\NAMT_BOT\Git\UnimportantProject_HAMT\Desktop\pages.py", line 27, in addData
    if (deskU.checkFieldOnIncosist(self,1)==True and len(bd.reqExecute(f"Select * from Equipment where Serial_Number='{serialNumber_field.value}'"))==0):
        ^^^^^^^^^^^^^^^^^^^^^^^^^^^^^^^^^^
  File "E:\PROJECT\Python\NAMT_BOT\Git\UnimportantProject_HAMT\utilits\utilits_desktop.py", line 131, in checkFieldOnIncosist
    if (self.page.controls[i].value=="" or self.page.controls[i].value==None):
        ^^^^^^^^^^^^^^^^^^^^^^^^^^^
AttributeError: 'Row' object has no attribute 'value'
[INFO] [2025-04-17 16:11:22,561] - main: App Started
[INFO] [2025-04-17 16:11:22,620] - database: Connected to database was successfull
[INFO] [2025-04-17 16:11:23,162] - pages: 'Start' page was openned
[INFO] [2025-04-17 16:11:59,077] - pages: 'Main' page was openned
[ERROR] [2025-04-17 16:13:08,024] - asyncio: Future exception was never retrieved
future: <Future finished exception=AttributeError("'Row' object has no attribute 'value'")>
Traceback (most recent call last):
  File "c:\Users\user\AppData\Local\Programs\Python\Python311\Lib\concurrent\futures\thread.py", line 58, in run
    result = self.fn(*self.args, **self.kwargs)
             ^^^^^^^^^^^^^^^^^^^^^^^^^^^^^^^^^^
  File "c:\Users\user\AppData\Local\Programs\Python\Python311\Lib\site-packages\flet\core\page.py", line 903, in wrapper
    handler(*args)
  File "E:\PROJECT\Python\NAMT_BOT\Git\UnimportantProject_HAMT\Desktop\pages.py", line 27, in addData
    if (deskU.checkFieldOnIncosist(self,1)==True and len(bd.reqExecute(f"Select * from Equipment where Serial_Number='{serialNumber_field.value}'"))==0):
        ^^^^^^^^^^^^^^^^^^^^^^^^^^^^^^^^^^
  File "E:\PROJECT\Python\NAMT_BOT\Git\UnimportantProject_HAMT\utilits\utilits_desktop.py", line 131, in checkFieldOnIncosist
    if (self.page.controls[i].value=="" or self.page.controls[i].value==None):
        ^^^^^^^^^^^^^^^^^^^^^^^^^^^
AttributeError: 'Row' object has no attribute 'value'
[INFO] [2025-04-17 16:13:19,161] - main: App Started
[INFO] [2025-04-17 16:13:19,314] - database: Connected to database was successfull
[INFO] [2025-04-17 16:13:19,873] - pages: 'Start' page was openned
[INFO] [2025-04-17 16:13:34,782] - pages: 'Main' page was openned
[INFO] [2025-04-17 16:14:51,116] - main: App Started
[INFO] [2025-04-17 16:14:51,170] - database: Connected to database was successfull
[INFO] [2025-04-17 16:14:51,671] - pages: 'Start' page was openned
[INFO] [2025-04-17 16:14:59,031] - pages: 'Main' page was openned
[ERROR] [2025-04-17 16:15:03,454] - asyncio: Future exception was never retrieved
future: <Future finished exception=AttributeError("'Row' object has no attribute 'value'")>
Traceback (most recent call last):
  File "c:\Users\user\AppData\Local\Programs\Python\Python311\Lib\concurrent\futures\thread.py", line 58, in run
    result = self.fn(*self.args, **self.kwargs)
             ^^^^^^^^^^^^^^^^^^^^^^^^^^^^^^^^^^
  File "c:\Users\user\AppData\Local\Programs\Python\Python311\Lib\site-packages\flet\core\page.py", line 903, in wrapper
    handler(*args)
  File "E:\PROJECT\Python\NAMT_BOT\Git\UnimportantProject_HAMT\Desktop\pages.py", line 27, in addData
    if (deskU.checkFieldOnIncosist(self,1)==True and len(bd.reqExecute(f"Select * from Equipment where Serial_Number='{serialNumber_field.value}'"))==0):
        ^^^^^^^^^^^^^^^^^^^^^^^^^^^^^^^^^^
  File "E:\PROJECT\Python\NAMT_BOT\Git\UnimportantProject_HAMT\utilits\utilits_desktop.py", line 131, in checkFieldOnIncosist
    if (self.page.controls[i].value=="" or self.page.controls[i].value==None and (type(self.page.controls[i]!=ft.Row) or type(self.page.controls[i]!=ft.Column))):
        ^^^^^^^^^^^^^^^^^^^^^^^^^^^
AttributeError: 'Row' object has no attribute 'value'
[INFO] [2025-04-17 16:15:48,246] - main: App Started
[INFO] [2025-04-17 16:15:48,303] - database: Connected to database was successfull
[INFO] [2025-04-17 16:15:48,898] - pages: 'Start' page was openned
[INFO] [2025-04-17 16:16:00,626] - pages: 'Main' page was openned
[ERROR] [2025-04-17 16:16:48,592] - asyncio: Future exception was never retrieved
future: <Future finished exception=AttributeError("'Row' object has no attribute 'value'")>
Traceback (most recent call last):
  File "c:\Users\user\AppData\Local\Programs\Python\Python311\Lib\concurrent\futures\thread.py", line 58, in run
    result = self.fn(*self.args, **self.kwargs)
             ^^^^^^^^^^^^^^^^^^^^^^^^^^^^^^^^^^
  File "c:\Users\user\AppData\Local\Programs\Python\Python311\Lib\site-packages\flet\core\page.py", line 903, in wrapper
    handler(*args)
  File "E:\PROJECT\Python\NAMT_BOT\Git\UnimportantProject_HAMT\Desktop\pages.py", line 27, in addData
    if (deskU.checkFieldOnIncosist(self,1)==True and len(bd.reqExecute(f"Select * from Equipment where Serial_Number='{serialNumber_field.value}'"))==0):
        ^^^^^^^^^^^^^^^^^^^^^^^^^^^^^^^^^^
  File "E:\PROJECT\Python\NAMT_BOT\Git\UnimportantProject_HAMT\utilits\utilits_desktop.py", line 131, in checkFieldOnIncosist
    if ((type(self.page.controls[i]!=ft.Row) or type(self.page.controls[i]!=ft.Column)) and (self.page.controls[i].value=="" or self.page.controls[i].value==None)):
                                                                                             ^^^^^^^^^^^^^^^^^^^^^^^^^^^
AttributeError: 'Row' object has no attribute 'value'
[INFO] [2025-04-17 16:17:22,535] - main: App Started
[INFO] [2025-04-17 16:17:22,593] - database: Connected to database was successfull
[INFO] [2025-04-17 16:17:23,109] - pages: 'Start' page was openned
[INFO] [2025-04-17 16:17:28,418] - pages: 'Main' page was openned
[ERROR] [2025-04-17 16:17:38,304] - asyncio: Future exception was never retrieved
future: <Future finished exception=AttributeError("'Row' object has no attribute 'value'")>
Traceback (most recent call last):
  File "c:\Users\user\AppData\Local\Programs\Python\Python311\Lib\concurrent\futures\thread.py", line 58, in run
    result = self.fn(*self.args, **self.kwargs)
             ^^^^^^^^^^^^^^^^^^^^^^^^^^^^^^^^^^
  File "c:\Users\user\AppData\Local\Programs\Python\Python311\Lib\site-packages\flet\core\page.py", line 903, in wrapper
    handler(*args)
  File "E:\PROJECT\Python\NAMT_BOT\Git\UnimportantProject_HAMT\Desktop\pages.py", line 27, in addData
    if (deskU.checkFieldOnIncosist(self,1)==True and len(bd.reqExecute(f"Select * from Equipment where Serial_Number='{serialNumber_field.value}'"))==0):
        ^^^^^^^^^^^^^^^^^^^^^^^^^^^^^^^^^^
  File "E:\PROJECT\Python\NAMT_BOT\Git\UnimportantProject_HAMT\utilits\utilits_desktop.py", line 131, in checkFieldOnIncosist
    if ((type(self.page.controls[i])!=ft.Row or type(self.page.controls[i])!=ft.Column) and (self.page.controls[i].value=="" or self.page.controls[i].value==None)):
                                                                                             ^^^^^^^^^^^^^^^^^^^^^^^^^^^
AttributeError: 'Row' object has no attribute 'value'
[INFO] [2025-04-17 16:18:23,887] - main: App Started
[INFO] [2025-04-17 16:18:23,940] - database: Connected to database was successfull
[INFO] [2025-04-17 16:18:24,387] - pages: 'Start' page was openned
[INFO] [2025-04-17 16:18:58,588] - main: App Started
[INFO] [2025-04-17 16:18:58,662] - database: Connected to database was successfull
[INFO] [2025-04-17 16:18:59,141] - pages: 'Start' page was openned
[INFO] [2025-04-17 16:19:23,802] - pages: 'Main' page was openned
[ERROR] [2025-04-17 16:19:30,138] - asyncio: Future exception was never retrieved
future: <Future finished exception=AttributeError("'Row' object has no attribute 'value'")>
Traceback (most recent call last):
  File "c:\Users\user\AppData\Local\Programs\Python\Python311\Lib\concurrent\futures\thread.py", line 58, in run
    result = self.fn(*self.args, **self.kwargs)
             ^^^^^^^^^^^^^^^^^^^^^^^^^^^^^^^^^^
  File "c:\Users\user\AppData\Local\Programs\Python\Python311\Lib\site-packages\flet\core\page.py", line 903, in wrapper
    handler(*args)
  File "E:\PROJECT\Python\NAMT_BOT\Git\UnimportantProject_HAMT\Desktop\pages.py", line 27, in addData
    if (deskU.checkFieldOnIncosist(self,1)==True and len(bd.reqExecute(f"Select * from Equipment where Serial_Number='{serialNumber_field.value}'"))==0):
        ^^^^^^^^^^^^^^^^^^^^^^^^^^^^^^^^^^
  File "E:\PROJECT\Python\NAMT_BOT\Git\UnimportantProject_HAMT\utilits\utilits_desktop.py", line 132, in checkFieldOnIncosist
    if((self.page.controls[i].value=="" or self.page.controls[i].value==None)):
        ^^^^^^^^^^^^^^^^^^^^^^^^^^^
AttributeError: 'Row' object has no attribute 'value'
[INFO] [2025-04-17 16:20:33,250] - main: App Started
[INFO] [2025-04-17 16:20:33,313] - database: Connected to database was successfull
[INFO] [2025-04-17 16:20:33,804] - pages: 'Start' page was openned
[INFO] [2025-04-17 16:20:38,270] - pages: 'Main' page was openned
[INFO] [2025-04-17 16:22:08,850] - main: App Started
[INFO] [2025-04-17 16:22:08,908] - database: Connected to database was successfull
[INFO] [2025-04-17 16:22:09,425] - pages: 'Start' page was openned
[INFO] [2025-04-17 16:22:13,951] - pages: 'Main' page was openned
[INFO] [2025-04-17 16:23:52,929] - main: App Started
[INFO] [2025-04-17 16:23:52,999] - database: Connected to database was successfull
[INFO] [2025-04-17 16:23:53,656] - pages: 'Start' page was openned
[INFO] [2025-04-17 17:20:20,093] - pages: 'Main' page was openned
[INFO] [2025-04-18 11:47:16,433] - main: App Started
[INFO] [2025-04-18 11:47:16,484] - database: Connected to database was successfull
[INFO] [2025-04-18 11:47:17,185] - pages: 'Start' page was openned
[INFO] [2025-04-18 11:47:27,099] - pages: 'Main' page was openned
[ERROR] [2025-04-18 11:47:28,587] - asyncio: Future exception was never retrieved
future: <Future finished exception=AssertionError('each visible DataRow must contain exactly as many visible DataCells as there are visible DataColumns (5)')>
Traceback (most recent call last):
  File "c:\Users\user\AppData\Local\Programs\Python\Python311\Lib\concurrent\futures\thread.py", line 58, in run
    result = self.fn(*self.args, **self.kwargs)
             ^^^^^^^^^^^^^^^^^^^^^^^^^^^^^^^^^^
  File "c:\Users\user\AppData\Local\Programs\Python\Python311\Lib\site-packages\flet\core\page.py", line 903, in wrapper
    handler(*args)
  File "E:\PROJECT\Python\NAMT_BOT\Git\UnimportantProject_HAMT\Desktop\pages.py", line 384, in <lambda>
    requestPageButton=ft.ElevatedButton("Заявки", icon=ft.icons.HOME_REPAIR_SERVICE, width=130, on_click=lambda _:request_page(page))
                                                                                                                  ^^^^^^^^^^^^^^^^^^
  File "E:\PROJECT\Python\NAMT_BOT\Git\UnimportantProject_HAMT\Desktop\pages.py", line 333, in request_page
    page.add(ft.Row([backButton,ft.Text(" ", width=30),menuBar]),table)
  File "c:\Users\user\AppData\Local\Programs\Python\Python311\Lib\site-packages\flet\core\page.py", line 740, in add
    r = self.__update(self)
        ^^^^^^^^^^^^^^^^^^^
  File "c:\Users\user\AppData\Local\Programs\Python\Python311\Lib\site-packages\flet\core\page.py", line 798, in __update
    commands, added_controls, removed_controls = self.__prepare_update(*controls)
                                                 ^^^^^^^^^^^^^^^^^^^^^^^^^^^^^^^^
  File "c:\Users\user\AppData\Local\Programs\Python\Python311\Lib\site-packages\flet\core\page.py", line 814, in __prepare_update
    control.build_update_commands(
  File "c:\Users\user\AppData\Local\Programs\Python\Python311\Lib\site-packages\flet\core\control.py", line 490, in build_update_commands
    innerCmds = ctrl._build_add_commands(
                ^^^^^^^^^^^^^^^^^^^^^^^^^
  File "c:\Users\user\AppData\Local\Programs\Python\Python311\Lib\site-packages\flet\core\control.py", line 545, in _build_add_commands
    childCmd = control._build_add_commands(
               ^^^^^^^^^^^^^^^^^^^^^^^^^^^^
  File "c:\Users\user\AppData\Local\Programs\Python\Python311\Lib\site-packages\flet\core\control.py", line 545, in _build_add_commands
    childCmd = control._build_add_commands(
               ^^^^^^^^^^^^^^^^^^^^^^^^^^^^
  File "c:\Users\user\AppData\Local\Programs\Python\Python311\Lib\site-packages\flet\core\control.py", line 545, in _build_add_commands
    childCmd = control._build_add_commands(
               ^^^^^^^^^^^^^^^^^^^^^^^^^^^^
  File "c:\Users\user\AppData\Local\Programs\Python\Python311\Lib\site-packages\flet\core\control.py", line 534, in _build_add_commands
    command = self._build_command(False)
              ^^^^^^^^^^^^^^^^^^^^^^^^^^
  File "c:\Users\user\AppData\Local\Programs\Python\Python311\Lib\site-packages\flet\core\control.py", line 561, in _build_command
    self.before_update()
  File "c:\Users\user\AppData\Local\Programs\Python\Python311\Lib\site-packages\flet\core\datatable.py", line 469, in before_update
    assert all(
AssertionError: each visible DataRow must contain exactly as many visible DataCells as there are visible DataColumns (5)
[INFO] [2025-04-18 11:49:09,987] - main: App Started
[INFO] [2025-04-18 11:49:10,041] - database: Connected to database was successfull
[INFO] [2025-04-18 11:49:10,967] - pages: 'Start' page was openned
[INFO] [2025-04-18 11:49:24,323] - pages: 'Main' page was openned
[INFO] [2025-04-18 11:54:53,545] - main: App Started
[INFO] [2025-04-18 11:54:53,785] - database: Connected to database was successfull
[INFO] [2025-04-18 11:54:54,682] - pages: 'Start' page was openned
[INFO] [2025-04-18 11:55:15,196] - pages: 'Main' page was openned
[INFO] [2025-04-18 11:55:47,258] - pages: 'Main' page was openned
[INFO] [2025-04-18 11:55:49,184] - pages: 'Main' page was openned
[INFO] [2025-04-18 11:55:58,108] - pages: 'Main' page was openned
[INFO] [2025-04-18 11:56:00,439] - pages: 'Main' page was openned
[INFO] [2025-04-18 11:56:02,185] - pages: 'Main' page was openned
[INFO] [2025-04-18 11:56:04,397] - pages: 'Main' page was openned
[INFO] [2025-04-18 12:05:19,752] - main: App Started
[INFO] [2025-04-18 12:05:19,825] - database: Connected to database was successfull
[INFO] [2025-04-18 12:05:20,441] - pages: 'Start' page was openned
[INFO] [2025-04-18 12:27:53,841] - pages: 'Main' page was openned
[INFO] [2025-04-18 12:28:14,317] - pages: 'Main' page was openned
[INFO] [2025-04-18 12:36:55,440] - main: App Started
[INFO] [2025-04-18 12:36:55,599] - database: Connected to database was successfull
[INFO] [2025-04-18 12:36:56,134] - pages: 'Start' page was openned
[INFO] [2025-04-18 12:37:04,017] - pages: 'Main' page was openned
[INFO] [2025-04-18 12:39:23,650] - main: App Started
[INFO] [2025-04-18 12:39:23,845] - database: Connected to database was successfull
[INFO] [2025-04-18 12:39:24,314] - pages: 'Start' page was openned
[INFO] [2025-04-18 12:39:28,521] - pages: 'Main' page was openned
[ERROR] [2025-04-18 12:39:34,268] - asyncio: Future exception was never retrieved
future: <Future finished exception=AttributeError("'ControlEvent' object has no attribute 'content'")>
Traceback (most recent call last):
  File "c:\Users\user\AppData\Local\Programs\Python\Python311\Lib\concurrent\futures\thread.py", line 58, in run
    result = self.fn(*self.args, **self.kwargs)
             ^^^^^^^^^^^^^^^^^^^^^^^^^^^^^^^^^^
  File "c:\Users\user\AppData\Local\Programs\Python\Python311\Lib\site-packages\flet\core\page.py", line 903, in wrapper
    handler(*args)
  File "E:\PROJECT\Python\NAMT_BOT\Git\UnimportantProject_HAMT\utilits\utilits_desktop.py", line 390, in viewData_mode
    viewMode_dialog=ft.AlertDialog(title=ft.Text("Просмотр данных"), actions=[ft.ElevatedButton("Выйти",on_click=lambda _:argc.page.close(viewMode_dialog))],content=ft.Text(argc.content.data["|"][0],size=20))
                                                                                                                                                                             ^^^^^^^^^^^^
AttributeError: 'ControlEvent' object has no attribute 'content'
[INFO] [2025-04-18 12:41:26,498] - main: App Started
[INFO] [2025-04-18 12:41:26,550] - database: Connected to database was successfull
[INFO] [2025-04-18 12:41:26,963] - pages: 'Start' page was openned
[INFO] [2025-04-18 12:41:29,891] - pages: 'Main' page was openned
[INFO] [2025-04-18 12:42:14,380] - main: App Started
[INFO] [2025-04-18 12:42:14,585] - database: Connected to database was successfull
[INFO] [2025-04-18 12:42:15,042] - pages: 'Start' page was openned
[INFO] [2025-04-18 12:42:32,922] - pages: 'Main' page was openned
[ERROR] [2025-04-18 12:42:36,288] - asyncio: Future exception was never retrieved
future: <Future finished exception=TypeError("string indices must be integers, not 'str'")>
Traceback (most recent call last):
  File "c:\Users\user\AppData\Local\Programs\Python\Python311\Lib\concurrent\futures\thread.py", line 58, in run
    result = self.fn(*self.args, **self.kwargs)
             ^^^^^^^^^^^^^^^^^^^^^^^^^^^^^^^^^^
  File "c:\Users\user\AppData\Local\Programs\Python\Python311\Lib\site-packages\flet\core\page.py", line 903, in wrapper
    handler(*args)
  File "E:\PROJECT\Python\NAMT_BOT\Git\UnimportantProject_HAMT\utilits\utilits_desktop.py", line 390, in viewData_mode
    viewMode_dialog=ft.AlertDialog(modal=True,title=ft.Text("Просмотр данных"),content=ft.Text(argc.control.data["|"][0],size=20), actions=[ft.ElevatedButton("Выйти",on_click=lambda _:argc.page.close(viewMode_dialog))])
                                                                                               ~~~~~~~~~~~~~~~~~^^^^^
TypeError: string indices must be integers, not 'str'
[INFO] [2025-04-18 12:42:56,199] - main: App Started
[INFO] [2025-04-18 12:42:56,270] - database: Connected to database was successfull
[INFO] [2025-04-18 12:42:56,854] - pages: 'Start' page was openned
[INFO] [2025-04-18 13:02:19,837] - pages: 'Main' page was openned
[INFO] [2025-04-18 13:02:53,589] - main: App Started
[INFO] [2025-04-18 13:02:53,748] - database: Connected to database was successfull
[INFO] [2025-04-18 13:02:54,226] - pages: 'Start' page was openned
[INFO] [2025-04-18 13:03:19,397] - pages: 'Main' page was openned
[INFO] [2025-04-18 13:03:52,471] - main: App Started
[INFO] [2025-04-18 13:03:52,528] - database: Connected to database was successfull
[INFO] [2025-04-18 13:03:52,942] - pages: 'Start' page was openned
[INFO] [2025-04-18 13:04:00,086] - pages: 'Main' page was openned
[INFO] [2025-04-18 13:04:11,493] - pages: 'Main' page was openned
[INFO] [2025-04-18 13:04:50,626] - main: App Started
[INFO] [2025-04-18 13:04:50,808] - database: Connected to database was successfull
[INFO] [2025-04-18 13:04:51,368] - pages: 'Start' page was openned
[INFO] [2025-04-18 13:05:03,479] - pages: 'Main' page was openned
[INFO] [2025-04-18 13:05:23,267] - pages: 'Main' page was openned
[INFO] [2025-04-18 13:07:19,684] - main: App Started
[INFO] [2025-04-18 13:07:19,882] - database: Connected to database was successfull
[INFO] [2025-04-18 13:07:20,775] - pages: 'Start' page was openned
[INFO] [2025-04-18 13:08:08,967] - pages: 'Main' page was openned
[INFO] [2025-04-18 13:08:35,914] - main: App Started
[INFO] [2025-04-18 13:08:35,966] - database: Connected to database was successfull
[INFO] [2025-04-18 13:10:17,893] - main: App Started
[INFO] [2025-04-18 13:10:17,955] - database: Connected to database was successfull
[INFO] [2025-04-18 13:10:18,446] - pages: 'Start' page was openned
[INFO] [2025-04-18 13:10:21,410] - pages: 'Main' page was openned
[INFO] [2025-04-18 13:10:24,050] - pages: 'Main' page was openned
[INFO] [2025-04-18 13:53:13,183] - main: App Started
[INFO] [2025-04-18 13:53:13,250] - database: Connected to database was successfull
[INFO] [2025-04-18 13:53:13,730] - pages: 'Start' page was openned
[INFO] [2025-04-18 13:53:19,296] - pages: 'Main' page was openned
[INFO] [2025-04-18 13:56:11,792] - main: App Started
[INFO] [2025-04-18 13:56:11,851] - database: Connected to database was successfull
[INFO] [2025-04-18 13:56:12,303] - pages: 'Start' page was openned
[INFO] [2025-04-18 13:56:16,882] - pages: 'Main' page was openned
[INFO] [2025-04-18 13:56:32,427] - pages: 'Main' page was openned
[INFO] [2025-04-18 14:13:42,233] - main: App Started
[INFO] [2025-04-18 14:13:42,286] - database: Connected to database was successfull
[INFO] [2025-04-18 14:13:42,713] - pages: 'Start' page was openned
[INFO] [2025-04-18 14:13:47,700] - pages: 'Main' page was openned
[INFO] [2025-04-18 14:15:08,338] - main: App Started
[INFO] [2025-04-18 14:15:08,396] - database: Connected to database was successfull
[INFO] [2025-04-18 14:15:08,830] - pages: 'Start' page was openned
[INFO] [2025-04-18 14:15:13,071] - pages: 'Main' page was openned
[INFO] [2025-04-18 14:16:22,032] - main: App Started
[INFO] [2025-04-18 14:16:22,190] - database: Connected to database was successfull
[INFO] [2025-04-18 14:16:22,654] - pages: 'Start' page was openned
[INFO] [2025-04-18 14:16:27,119] - pages: 'Main' page was openned
[ERROR] [2025-04-18 14:16:34,383] - asyncio: Future exception was never retrieved
future: <Future finished exception=AssertionError('each visible DataRow must contain exactly as many visible DataCells as there are visible DataColumns (6)')>
Traceback (most recent call last):
  File "c:\Users\user\AppData\Local\Programs\Python\Python311\Lib\concurrent\futures\thread.py", line 58, in run
    result = self.fn(*self.args, **self.kwargs)
             ^^^^^^^^^^^^^^^^^^^^^^^^^^^^^^^^^^
  File "c:\Users\user\AppData\Local\Programs\Python\Python311\Lib\site-packages\flet\core\page.py", line 903, in wrapper
    handler(*args)
  File "E:\PROJECT\Python\NAMT_BOT\Git\UnimportantProject_HAMT\utilits\utilits_desktop.py", line 335, in __changeData
    self.updateTable(argc)
  File "E:\PROJECT\Python\NAMT_BOT\Git\UnimportantProject_HAMT\utilits\utilits_desktop.py", line 291, in updateTable
    argc.page.update()
  File "c:\Users\user\AppData\Local\Programs\Python\Python311\Lib\site-packages\flet\core\page.py", line 732, in update
    r = self.__update(self)
        ^^^^^^^^^^^^^^^^^^^
  File "c:\Users\user\AppData\Local\Programs\Python\Python311\Lib\site-packages\flet\core\page.py", line 798, in __update
    commands, added_controls, removed_controls = self.__prepare_update(*controls)
                                                 ^^^^^^^^^^^^^^^^^^^^^^^^^^^^^^^^
  File "c:\Users\user\AppData\Local\Programs\Python\Python311\Lib\site-packages\flet\core\page.py", line 814, in __prepare_update
    control.build_update_commands(
  File "c:\Users\user\AppData\Local\Programs\Python\Python311\Lib\site-packages\flet\core\control.py", line 477, in build_update_commands
    ctrl.build_update_commands(
  File "c:\Users\user\AppData\Local\Programs\Python\Python311\Lib\site-packages\flet\core\control.py", line 477, in build_update_commands
    ctrl.build_update_commands(
  File "c:\Users\user\AppData\Local\Programs\Python\Python311\Lib\site-packages\flet\core\control.py", line 477, in build_update_commands
    ctrl.build_update_commands(
  [Previous line repeated 1 more time]
  File "c:\Users\user\AppData\Local\Programs\Python\Python311\Lib\site-packages\flet\core\control.py", line 398, in build_update_commands
    update_cmd = self._build_command(update=True)
                 ^^^^^^^^^^^^^^^^^^^^^^^^^^^^^^^^
  File "c:\Users\user\AppData\Local\Programs\Python\Python311\Lib\site-packages\flet\core\control.py", line 561, in _build_command
    self.before_update()
  File "c:\Users\user\AppData\Local\Programs\Python\Python311\Lib\site-packages\flet\core\datatable.py", line 469, in before_update
    assert all(
AssertionError: each visible DataRow must contain exactly as many visible DataCells as there are visible DataColumns (6)
[INFO] [2025-04-18 14:18:02,643] - main: App Started
[INFO] [2025-04-18 14:18:02,699] - database: Connected to database was successfull
[INFO] [2025-04-18 14:18:03,153] - pages: 'Start' page was openned
[INFO] [2025-04-18 14:18:07,503] - pages: 'Main' page was openned
[INFO] [2025-04-18 14:21:04,752] - main: App Started
[INFO] [2025-04-18 14:21:04,810] - database: Connected to database was successfull
[INFO] [2025-04-18 14:21:05,270] - pages: 'Start' page was openned
[INFO] [2025-04-18 14:21:11,290] - pages: 'Main' page was openned
[INFO] [2025-04-18 14:22:05,235] - main: App Started
[INFO] [2025-04-18 14:22:05,450] - database: Connected to database was successfull
[INFO] [2025-04-18 14:22:05,916] - pages: 'Start' page was openned
[INFO] [2025-04-18 14:22:16,046] - pages: 'Main' page was openned
[ERROR] [2025-04-18 14:24:05,654] - asyncio: Future exception was never retrieved
future: <Future finished exception=AssertionError('each visible DataRow must contain exactly as many visible DataCells as there are visible DataColumns (6)')>
Traceback (most recent call last):
  File "c:\Users\user\AppData\Local\Programs\Python\Python311\Lib\concurrent\futures\thread.py", line 58, in run
    result = self.fn(*self.args, **self.kwargs)
             ^^^^^^^^^^^^^^^^^^^^^^^^^^^^^^^^^^
  File "c:\Users\user\AppData\Local\Programs\Python\Python311\Lib\site-packages\flet\core\page.py", line 903, in wrapper
    handler(*args)
  File "E:\PROJECT\Python\NAMT_BOT\Git\UnimportantProject_HAMT\utilits\utilits_desktop.py", line 335, in __changeData
    self.updateTable(argc)
  File "E:\PROJECT\Python\NAMT_BOT\Git\UnimportantProject_HAMT\utilits\utilits_desktop.py", line 291, in updateTable
    argc.page.update()
  File "c:\Users\user\AppData\Local\Programs\Python\Python311\Lib\site-packages\flet\core\page.py", line 732, in update
    r = self.__update(self)
        ^^^^^^^^^^^^^^^^^^^
  File "c:\Users\user\AppData\Local\Programs\Python\Python311\Lib\site-packages\flet\core\page.py", line 798, in __update
    commands, added_controls, removed_controls = self.__prepare_update(*controls)
                                                 ^^^^^^^^^^^^^^^^^^^^^^^^^^^^^^^^
  File "c:\Users\user\AppData\Local\Programs\Python\Python311\Lib\site-packages\flet\core\page.py", line 814, in __prepare_update
    control.build_update_commands(
  File "c:\Users\user\AppData\Local\Programs\Python\Python311\Lib\site-packages\flet\core\control.py", line 477, in build_update_commands
    ctrl.build_update_commands(
  File "c:\Users\user\AppData\Local\Programs\Python\Python311\Lib\site-packages\flet\core\control.py", line 477, in build_update_commands
    ctrl.build_update_commands(
  File "c:\Users\user\AppData\Local\Programs\Python\Python311\Lib\site-packages\flet\core\control.py", line 477, in build_update_commands
    ctrl.build_update_commands(
  [Previous line repeated 1 more time]
  File "c:\Users\user\AppData\Local\Programs\Python\Python311\Lib\site-packages\flet\core\control.py", line 398, in build_update_commands
    update_cmd = self._build_command(update=True)
                 ^^^^^^^^^^^^^^^^^^^^^^^^^^^^^^^^
  File "c:\Users\user\AppData\Local\Programs\Python\Python311\Lib\site-packages\flet\core\control.py", line 561, in _build_command
    self.before_update()
  File "c:\Users\user\AppData\Local\Programs\Python\Python311\Lib\site-packages\flet\core\datatable.py", line 469, in before_update
    assert all(
AssertionError: each visible DataRow must contain exactly as many visible DataCells as there are visible DataColumns (6)
[INFO] [2025-04-18 14:25:04,144] - main: App Started
[INFO] [2025-04-18 14:25:04,348] - database: Connected to database was successfull
[INFO] [2025-04-18 14:25:04,811] - pages: 'Start' page was openned
[INFO] [2025-04-18 14:25:09,745] - pages: 'Main' page was openned
[INFO] [2025-04-18 14:28:21,974] - main: App Started
[INFO] [2025-04-18 14:28:22,025] - database: Connected to database was successfull
[INFO] [2025-04-18 14:28:22,491] - pages: 'Start' page was openned
[INFO] [2025-04-18 14:28:26,904] - pages: 'Main' page was openned
[INFO] [2025-04-18 14:30:29,533] - main: App Started
[INFO] [2025-04-18 14:30:29,694] - database: Connected to database was successfull
[INFO] [2025-04-18 14:30:30,131] - pages: 'Start' page was openned
[INFO] [2025-04-18 14:30:35,142] - pages: 'Main' page was openned
[INFO] [2025-04-18 14:32:59,539] - main: App Started
[INFO] [2025-04-18 14:32:59,699] - database: Connected to database was successfull
[INFO] [2025-04-18 14:33:00,147] - pages: 'Start' page was openned
[INFO] [2025-04-18 14:33:03,751] - pages: 'Main' page was openned
[INFO] [2025-04-18 14:34:31,372] - main: App Started
[INFO] [2025-04-18 14:34:31,434] - database: Connected to database was successfull
[INFO] [2025-04-18 14:34:32,337] - pages: 'Start' page was openned
[INFO] [2025-04-18 14:34:36,547] - pages: 'Main' page was openned
[ERROR] [2025-04-18 14:34:43,890] - asyncio: Future exception was never retrieved
future: <Future finished exception=AttributeError("'TextField' object has no attribute 'isdigit'")>
Traceback (most recent call last):
  File "c:\Users\user\AppData\Local\Programs\Python\Python311\Lib\concurrent\futures\thread.py", line 58, in run
    result = self.fn(*self.args, **self.kwargs)
             ^^^^^^^^^^^^^^^^^^^^^^^^^^^^^^^^^^
  File "c:\Users\user\AppData\Local\Programs\Python\Python311\Lib\site-packages\flet\core\page.py", line 903, in wrapper
    handler(*args)
  File "E:\PROJECT\Python\NAMT_BOT\Git\UnimportantProject_HAMT\utilits\utilits_desktop.py", line 219, in editMode
    if (cell.content.isdigit()==True):
        ^^^^^^^^^^^^^^^^^^^^
AttributeError: 'TextField' object has no attribute 'isdigit'
[ERROR] [2025-04-18 14:34:47,878] - asyncio: Future exception was never retrieved
future: <Future finished exception=AttributeError("'TextField' object has no attribute 'isdigit'")>
Traceback (most recent call last):
  File "c:\Users\user\AppData\Local\Programs\Python\Python311\Lib\concurrent\futures\thread.py", line 58, in run
    result = self.fn(*self.args, **self.kwargs)
             ^^^^^^^^^^^^^^^^^^^^^^^^^^^^^^^^^^
  File "c:\Users\user\AppData\Local\Programs\Python\Python311\Lib\site-packages\flet\core\page.py", line 903, in wrapper
    handler(*args)
  File "E:\PROJECT\Python\NAMT_BOT\Git\UnimportantProject_HAMT\utilits\utilits_desktop.py", line 219, in editMode
    if (cell.content.isdigit()==True):
        ^^^^^^^^^^^^^^^^^^^^
AttributeError: 'TextField' object has no attribute 'isdigit'
[INFO] [2025-04-18 14:35:19,261] - main: App Started
[INFO] [2025-04-18 14:35:19,412] - database: Connected to database was successfull
[INFO] [2025-04-18 14:35:19,843] - pages: 'Start' page was openned
[INFO] [2025-04-18 14:35:24,066] - pages: 'Main' page was openned
[INFO] [2025-04-18 14:36:48,597] - main: App Started
[INFO] [2025-04-18 14:36:48,649] - database: Connected to database was successfull
[INFO] [2025-04-18 14:36:49,088] - pages: 'Start' page was openned
[INFO] [2025-04-18 14:36:54,004] - pages: 'Main' page was openned
[INFO] [2025-04-18 14:45:07,104] - main: App Started
[INFO] [2025-04-18 14:45:07,156] - database: Connected to database was successfull
[INFO] [2025-04-18 14:45:07,586] - pages: 'Start' page was openned
[INFO] [2025-04-18 14:45:15,481] - pages: 'Main' page was openned
[ERROR] [2025-04-18 14:45:26,727] - asyncio: Future exception was never retrieved
future: <Future finished exception=AttributeError("'int' object has no attribute 'content'")>
Traceback (most recent call last):
  File "c:\Users\user\AppData\Local\Programs\Python\Python311\Lib\concurrent\futures\thread.py", line 58, in run
    result = self.fn(*self.args, **self.kwargs)
             ^^^^^^^^^^^^^^^^^^^^^^^^^^^^^^^^^^
  File "c:\Users\user\AppData\Local\Programs\Python\Python311\Lib\site-packages\flet\core\page.py", line 903, in wrapper
    handler(*args)
  File "E:\PROJECT\Python\NAMT_BOT\Git\UnimportantProject_HAMT\utilits\utilits_desktop.py", line 221, in editMode
    cell.content.on_click=self.changeCellData
    ^^^^^^^^^^^^
AttributeError: 'int' object has no attribute 'content'
[INFO] [2025-04-18 14:45:56,044] - main: App Started
[INFO] [2025-04-18 14:45:56,108] - database: Connected to database was successfull
[INFO] [2025-04-18 14:45:56,537] - pages: 'Start' page was openned
[INFO] [2025-04-18 14:46:03,049] - pages: 'Main' page was openned
[ERROR] [2025-04-18 14:46:10,672] - asyncio: Future exception was never retrieved
future: <Future finished exception=TypeError("'DataRow' object is not subscriptable")>
Traceback (most recent call last):
  File "c:\Users\user\AppData\Local\Programs\Python\Python311\Lib\concurrent\futures\thread.py", line 58, in run
    result = self.fn(*self.args, **self.kwargs)
             ^^^^^^^^^^^^^^^^^^^^^^^^^^^^^^^^^^
  File "c:\Users\user\AppData\Local\Programs\Python\Python311\Lib\site-packages\flet\core\page.py", line 903, in wrapper
    handler(*args)
  File "E:\PROJECT\Python\NAMT_BOT\Git\UnimportantProject_HAMT\utilits\utilits_desktop.py", line 221, in editMode
    i[cell].content.on_click=self.changeCellData
    ~^^^^^^
TypeError: 'DataRow' object is not subscriptable
[INFO] [2025-04-18 14:47:00,473] - main: App Started
[INFO] [2025-04-18 14:47:00,527] - database: Connected to database was successfull
[INFO] [2025-04-18 14:47:01,030] - pages: 'Start' page was openned
[INFO] [2025-04-18 14:47:06,014] - pages: 'Main' page was openned
[INFO] [2025-04-18 14:47:46,986] - pages: 'Main' page was openned
[INFO] [2025-04-18 15:00:56,352] - main: App Started
[INFO] [2025-04-18 15:00:56,514] - database: Connected to database was successfull
[INFO] [2025-04-18 15:00:56,999] - pages: 'Start' page was openned
[INFO] [2025-04-18 15:01:01,610] - pages: 'Main' page was openned
[INFO] [2025-04-18 15:02:08,709] - main: App Started
[INFO] [2025-04-18 15:02:08,761] - database: Connected to database was successfull
[INFO] [2025-04-18 15:02:09,292] - pages: 'Start' page was openned
[INFO] [2025-04-18 15:02:14,733] - pages: 'Main' page was openned
[INFO] [2025-04-18 16:27:06,645] - main: App Started
[INFO] [2025-04-18 16:27:06,696] - database: Connected to database was successfull
[INFO] [2025-04-18 16:27:07,393] - pages: 'Start' page was openned
[INFO] [2025-04-18 16:27:16,685] - pages: 'Main' page was openned
